2020-05-04 16:55:39,953 ERROR: Exception on /auth/reset_password [POST] [in /home/miguel/flask_bug_tracker/venv/lib/python3.6/site-packages/flask/app.py:1891]
Traceback (most recent call last):
  File "/home/miguel/flask_bug_tracker/venv/lib/python3.6/site-packages/flask/app.py", line 2446, in wsgi_app
    response = self.full_dispatch_request()
  File "/home/miguel/flask_bug_tracker/venv/lib/python3.6/site-packages/flask/app.py", line 1951, in full_dispatch_request
    rv = self.handle_user_exception(e)
  File "/home/miguel/flask_bug_tracker/venv/lib/python3.6/site-packages/flask/app.py", line 1820, in handle_user_exception
    reraise(exc_type, exc_value, tb)
  File "/home/miguel/flask_bug_tracker/venv/lib/python3.6/site-packages/flask/_compat.py", line 39, in reraise
    raise value
  File "/home/miguel/flask_bug_tracker/venv/lib/python3.6/site-packages/flask/app.py", line 1949, in full_dispatch_request
    rv = self.dispatch_request()
  File "/home/miguel/flask_bug_tracker/venv/lib/python3.6/site-packages/flask/app.py", line 1935, in dispatch_request
    return self.view_functions[rule.endpoint](**req.view_args)
  File "/home/miguel/flask_bug_tracker/app/auth/routes.py", line 81, in reset_request
    send_reset_email(user)
  File "/home/miguel/flask_bug_tracker/app/auth/utils.py", line 34, in send_reset_email
    mail.send(msg)
  File "/home/miguel/flask_bug_tracker/venv/lib/python3.6/site-packages/flask_mail.py", line 491, in send
    with self.connect() as connection:
  File "/home/miguel/flask_bug_tracker/venv/lib/python3.6/site-packages/flask_mail.py", line 144, in __enter__
    self.host = self.configure_host()
  File "/home/miguel/flask_bug_tracker/venv/lib/python3.6/site-packages/flask_mail.py", line 158, in configure_host
    host = smtplib.SMTP(self.mail.server, self.mail.port)
  File "/usr/lib/python3.6/smtplib.py", line 251, in __init__
    (code, msg) = self.connect(host, port)
  File "/usr/lib/python3.6/smtplib.py", line 336, in connect
    self.sock = self._get_socket(host, port, self.timeout)
  File "/usr/lib/python3.6/smtplib.py", line 307, in _get_socket
    self.source_address)
  File "/usr/lib/python3.6/socket.py", line 724, in create_connection
    raise err
  File "/usr/lib/python3.6/socket.py", line 713, in create_connection
    sock.connect(sa)
TimeoutError: [Errno 110] Connection timed out
2020-05-05 14:40:33,360 INFO: Bug Tracker startup [in /home/miguel/flask_bug_tracker/app/__init__.py:64]
2020-05-05 14:40:33,518 INFO: Bug Tracker startup [in /home/miguel/flask_bug_tracker/app/__init__.py:64]
2020-05-05 14:40:33,525 INFO: Bug Tracker startup [in /home/miguel/flask_bug_tracker/app/__init__.py:64]
2020-05-05 14:41:27,878 INFO: Bug Tracker startup [in /home/miguel/flask_bug_tracker/app/__init__.py:64]
2020-05-05 14:43:42,141 INFO: Bug Tracker startup [in /home/miguel/flask_bug_tracker/app/__init__.py:64]
2020-05-05 14:45:30,382 INFO: Bug Tracker startup [in /home/miguel/flask_bug_tracker/app/__init__.py:64]
2020-05-05 14:53:29,025 INFO: Bug Tracker startup [in /home/miguel/flask_bug_tracker/app/__init__.py:64]
2020-05-06 05:02:11,111 INFO: Bug Tracker startup [in /home/miguel/flask_bug_tracker/app/__init__.py:64]
2020-05-06 05:16:29,448 INFO: Bug Tracker startup [in /home/miguel/flask_bug_tracker/app/__init__.py:64]
2020-05-06 05:16:29,503 INFO: Bug Tracker startup [in /home/miguel/flask_bug_tracker/app/__init__.py:64]
2020-05-06 05:16:29,534 INFO: Bug Tracker startup [in /home/miguel/flask_bug_tracker/app/__init__.py:64]
2020-05-06 05:26:29,743 INFO: Bug Tracker startup [in /home/miguel/flask_bug_tracker/app/__init__.py:64]
2020-05-06 05:26:29,779 INFO: Bug Tracker startup [in /home/miguel/flask_bug_tracker/app/__init__.py:64]
2020-05-06 05:26:29,812 INFO: Bug Tracker startup [in /home/miguel/flask_bug_tracker/app/__init__.py:64]
2020-05-07 07:17:35,754 INFO: Bug Tracker startup [in /home/miguel/flask_bug_tracker/app/__init__.py:64]
2020-05-07 07:20:07,641 INFO: Bug Tracker startup [in /home/miguel/flask_bug_tracker/app/__init__.py:64]
2020-05-07 07:20:07,733 INFO: Bug Tracker startup [in /home/miguel/flask_bug_tracker/app/__init__.py:64]
2020-05-07 07:20:07,771 INFO: Bug Tracker startup [in /home/miguel/flask_bug_tracker/app/__init__.py:64]
2020-05-07 15:32:15,635 INFO: Bug Tracker startup [in /home/miguel/flask_bug_tracker/app/__init__.py:64]
2020-05-07 15:32:15,711 INFO: Bug Tracker startup [in /home/miguel/flask_bug_tracker/app/__init__.py:64]
2020-05-07 15:32:15,742 INFO: Bug Tracker startup [in /home/miguel/flask_bug_tracker/app/__init__.py:64]
2020-05-07 15:36:20,600 INFO: Bug Tracker startup [in /home/miguel/flask_bug_tracker/app/__init__.py:64]
2020-05-07 15:36:20,608 INFO: Bug Tracker startup [in /home/miguel/flask_bug_tracker/app/__init__.py:64]
2020-05-07 15:36:20,652 INFO: Bug Tracker startup [in /home/miguel/flask_bug_tracker/app/__init__.py:64]
2020-05-07 15:39:49,045 INFO: Bug Tracker startup [in /home/miguel/flask_bug_tracker/app/__init__.py:64]
2020-05-07 15:39:49,188 INFO: Bug Tracker startup [in /home/miguel/flask_bug_tracker/app/__init__.py:64]
2020-05-07 15:39:49,190 INFO: Bug Tracker startup [in /home/miguel/flask_bug_tracker/app/__init__.py:64]
2020-05-07 15:40:57,813 INFO: Bug Tracker startup [in /home/miguel/flask_bug_tracker/app/__init__.py:64]
2020-05-07 15:40:57,969 INFO: Bug Tracker startup [in /home/miguel/flask_bug_tracker/app/__init__.py:64]
2020-05-07 15:40:57,990 INFO: Bug Tracker startup [in /home/miguel/flask_bug_tracker/app/__init__.py:64]
2020-05-07 15:49:55,424 INFO: Bug Tracker startup [in /home/miguel/flask_bug_tracker/app/__init__.py:64]
2020-05-07 15:49:55,465 INFO: Bug Tracker startup [in /home/miguel/flask_bug_tracker/app/__init__.py:64]
2020-05-07 15:49:55,490 INFO: Bug Tracker startup [in /home/miguel/flask_bug_tracker/app/__init__.py:64]
